<?xml version="1.0"?>
<robot name="autonomous_car" xmlns:xacro="http://www.ros.org/wiki/xacro">

<xacro:macro name="fixed_offset_joint" params="parent child offset rotation axis">
    <joint name="${parent}_to_${child}" type="fixed">
        <parent link="${parent}"/>
        <child link="${child}"/>
        <origin xyz="${offset}" rpy="${rotation}" />
        <axis xyz="${axis}"/>
    </joint>
</xacro:macro>

<xacro:macro name="hinge_joint" params="parent child offset rotation axis">
    <joint name="${child}_joint" type="revolute">
        <parent link="${parent}"/>
        <child link="${child}"/>
        <origin xyz="${offset}" rpy="${rotation}" />
        <axis xyz="${axis}"/>
        <limit lower="-${steering_wheel_angle_limit}" upper="${steering_wheel_angle_limit}" effort="10000000" velocity="10000000"/>
    </joint>
</xacro:macro>

<xacro:macro name="wheel_joint" params="parent child offset rotation axis">
    <joint name="${child}_joint" type="continuous">
        <parent link="${parent}"/>
        <child link="${child}"/>
        <origin xyz="${offset}" rpy="${rotation}" />
        <axis xyz="${axis}"/>
    </joint>
</xacro:macro>

</robot>
